2025-03-08 04:40:00,245 INFO    MainThread:1874 [wandb_init.py:setup_run_log_directory():647] Logging user logs to /content/atlas-gan/wandb/run-20250308_044000-5atto3li/logs/debug.log
2025-03-08 04:40:00,246 INFO    MainThread:1874 [wandb_init.py:setup_run_log_directory():648] Logging internal logs to /content/atlas-gan/wandb/run-20250308_044000-5atto3li/logs/debug-internal.log
2025-03-08 04:40:00,246 INFO    MainThread:1874 [wandb_init.py:init():761] calling init triggers
2025-03-08 04:40:00,246 INFO    MainThread:1874 [wandb_init.py:init():766] wandb.init called with sweep_config: {}
config: {'latent_dim': 100, 'batch_size': 64, 'learning_rate': 0.0002, 'num_epochs': 10, '_wandb': {}}
2025-03-08 04:40:00,247 INFO    MainThread:1874 [wandb_init.py:init():784] starting backend
2025-03-08 04:40:00,247 INFO    MainThread:1874 [wandb_init.py:init():788] sending inform_init request
2025-03-08 04:40:00,249 INFO    MainThread:1874 [backend.py:_multiprocessing_setup():97] multiprocessing start_methods=fork,spawn,forkserver, using: spawn
2025-03-08 04:40:00,249 INFO    MainThread:1874 [wandb_init.py:init():803] backend started and connected
2025-03-08 04:40:00,261 INFO    MainThread:1874 [wandb_run.py:_label_probe_notebook():1204] probe notebook
2025-03-08 04:40:01,095 INFO    MainThread:1874 [wandb_init.py:init():896] updated telemetry
2025-03-08 04:40:01,101 INFO    MainThread:1874 [wandb_init.py:init():920] communicating run to backend with 300.0 second timeout
2025-03-08 04:45:01,105 ERROR   MainThread:1874 [wandb_init.py:init():1481] error in wandb.init()
Traceback (most recent call last):
  File "/usr/lib/python3.11/asyncio/tasks.py", line 500, in wait_for
    return fut.result()
           ^^^^^^^^^^^^
  File "/usr/lib/python3.11/asyncio/locks.py", line 213, in wait
    await fut
asyncio.exceptions.CancelledError

The above exception was the direct cause of the following exception:

Traceback (most recent call last):
  File "/usr/local/lib/python3.11/dist-packages/wandb/sdk/mailbox/handles.py", line 141, in wait_async
  File "/usr/lib/python3.11/asyncio/tasks.py", line 502, in wait_for
    raise exceptions.TimeoutError() from exc
TimeoutError

The above exception was the direct cause of the following exception:

Traceback (most recent call last):
  File "/usr/local/lib/python3.11/dist-packages/wandb/sdk/wandb_init.py", line 946, in init
    )
      
  File "/usr/local/lib/python3.11/dist-packages/wandb/sdk/mailbox/wait_with_progress.py", line 23, in wait_with_progress
    """
        
  File "/usr/local/lib/python3.11/dist-packages/wandb/sdk/mailbox/wait_with_progress.py", line 86, in wait_all_with_progress
  File "/usr/local/lib/python3.11/dist-packages/wandb/sdk/lib/asyncio_compat.py", line 30, in run
    return future.result()
           ^^^^^^^^^^^^^^^
  File "/usr/lib/python3.11/concurrent/futures/_base.py", line 456, in result
    return self.__get_result()
           ^^^^^^^^^^^^^^^^^^^
  File "/usr/lib/python3.11/concurrent/futures/_base.py", line 401, in __get_result
    raise self._exception
  File "/usr/lib/python3.11/concurrent/futures/thread.py", line 58, in run
    result = self.fn(*self.args, **self.kwargs)
             ^^^^^^^^^^^^^^^^^^^^^^^^^^^^^^^^^^
  File "/usr/local/lib/python3.11/dist-packages/wandb/sdk/lib/asyncio_compat.py", line 74, in run
    return asyncio.run(self._run_or_cancel(fn))
           ^^^^^^^^^^^^^^^^^^^^^^^^^^^^^^^^^^^^
  File "/usr/lib/python3.11/asyncio/runners.py", line 190, in run
    return runner.run(main)
           ^^^^^^^^^^^^^^^^
  File "/usr/lib/python3.11/asyncio/runners.py", line 118, in run
    return self._loop.run_until_complete(task)
           ^^^^^^^^^^^^^^^^^^^^^^^^^^^^^^^^^^^
  File "/usr/lib/python3.11/asyncio/base_events.py", line 654, in run_until_complete
    return future.result()
           ^^^^^^^^^^^^^^^
  File "/usr/local/lib/python3.11/dist-packages/wandb/sdk/lib/asyncio_compat.py", line 98, in _run_or_cancel
    return fn_task.result()
           ^^^^^^^^^^^^^^^^
  File "/usr/local/lib/python3.11/dist-packages/wandb/sdk/mailbox/wait_with_progress.py", line 81, in progress_loop_with_timeout
  File "/usr/local/lib/python3.11/dist-packages/wandb/sdk/mailbox/wait_with_progress.py", line 129, in _wait_handles_async
  File "/usr/lib/python3.11/contextlib.py", line 217, in __aexit__
    await anext(self.gen)
  File "/usr/local/lib/python3.11/dist-packages/wandb/sdk/lib/asyncio_compat.py", line 190, in open_task_group
    await task_group._wait_all()
  File "/usr/local/lib/python3.11/dist-packages/wandb/sdk/lib/asyncio_compat.py", line 159, in _wait_all
    raise exc
  File "/usr/local/lib/python3.11/dist-packages/wandb/sdk/mailbox/wait_with_progress.py", line 127, in wait_single
    handle = handle_list[index]
                     ~~~^^^^^^^^
  File "/usr/local/lib/python3.11/dist-packages/wandb/sdk/mailbox/handles.py", line 150, in wait_async
TimeoutError: Timed out waiting for response on czgm42oggkgc

During handling of the above exception, another exception occurred:

Traceback (most recent call last):
  File "/usr/local/lib/python3.11/dist-packages/wandb/sdk/wandb_init.py", line 1471, in init
    if wl:
           
  File "/usr/local/lib/python3.11/dist-packages/wandb/sdk/wandb_init.py", line 959, in init
wandb.errors.errors.CommError: Run initialization has timed out after 300.0 sec. Please try increasing the timeout with the `init_timeout` setting: `wandb.init(settings=wandb.Settings(init_timeout=120))`.
